Workbook

Sheet Parámetros
A1: PODCAST FHC — PARÁMETROS DEL PRESUPUESTO
A3: Proyecto | B3: Podcast Friedman Hayek Center — Temporada 1
A4: Tipo de cambio de referencia | C4: ◄ COMPLETAR. ARS por 1 USD. Toda la conversión a pesos del archivo usa esta celda.
A5: Fecha de cotización del TC | C5: ◄ COMPLETAR. Fecha de corte del tipo de cambio usado.
A6: Escenario de equipamiento | B6: Recomendado | C6: Opciones: Austero / Recomendado / Premium. Cambiar acá recalcula la hoja Resumen.
A7: Cantidad de episodios | B7: 12 | C7: Temporada 1. Cada episodio adicional suma solo OPEX.
A8: Cadencia de publicación (días) | B8: 20
A9: Primera publicación | B9: 05/11/2026
A10: Última publicación | B10: 14/06/2027
A11: Contingencia | B11: 0.1 | C11: Sobre el subtotal.
A12: Episodios con pauta paga | B12: 6 | C12: De 12. Ver §7.5 del documento.
A14: NOTA
A15: Los valores en USD son estimaciones de referencia para dimensionar el proyecto, no cotizaciones en firme. Antes de la aprobación final hay que pedir tres cotizaciones por rubro.

Sheet CAPEX
A1: CAPEX — INVERSIÓN DE ÚNICA VEZ (activo que queda en UCEMA)
A3: Rubro | B3: Ítem | C3: Cant. Austero | D3: Unit. Austero | E3: Total Austero | F3: Cant. Recom. | G3: Unit. Recom. | H3: Total Recom. | I3: Cant. Premium | J3: Unit. Premium | K3: Total Premium
A4: VIDEO | B4: Cámara mirrorless con lente | C4: 2 | D4: 400 | E4: =C4*D4 | F4: 3 | G4: 700 | H4: =F4*G4 | I4: 3 | J4: 1400 | K4: =I4*J4
B5: Trípode de cámara | C5: 2 | D5: 75 | E5: =C5*D5 | F5: 3 | G5: 90 | H5: =F5*G5 | I5: 3 | J5: 150 | K5: =I5*J5
B6: Tarjeta de memoria de alta velocidad | C6: 4 | D6: 25 | E6: =C6*D6 | F6: 6 | G6: 30 | H6: =F6*G6 | I6: 6 | J6: 45 | K6: =I6*J6
B7: Alimentación continua (dummy battery) | C7: 0 | D7: 0 | E7: =C7*D7 | F7: 3 | G7: 35 | H7: =F7*G7 | I7: 3 | J7: 45 | K7: =I7*J7
B8: Switcher de corte en vivo | C8: 0 | D8: 0 | E8: =C8*D8 | F8: 0 | G8: 0 | H8: =F8*G8 | I8: 1 | J8: 300 | K8: =I8*J8
B9: Cables HDMI, soportes y accesorios | C9: 1 | D9: 80 | E9: =C9*D9 | F9: 1 | G9: 100 | H9: =F9*G9 | I9: 1 | J9: 25 | K9: =I9*J9
B10: Claqueta de sincronización | C10: 1 | D10: 20 | E10: =C10*D10 | F10: 1 | G10: 20 | H10: =F10*G10 | I10: 1 | J10: 20 | K10: =I10*J10
B11: Subtotal VIDEO | E11: =SUM(E4:E10) | H11: =SUM(H4:H10) | K11: =SUM(K4:K10)
A13: AUDIO | B13: Micrófono dinámico de podcast | C13: 4 | D13: 70 | E13: =C13*D13 | F13: 4 | G13: 130 | H13: =F13*G13 | I13: 4 | J13: 320 | K13: =I13*J13
B14: Brazo articulado para micrófono | C14: 4 | D14: 45 | E14: =C14*D14 | F14: 4 | G14: 100 | H14: =F14*G14 | I14: 4 | J14: 120 | K14: =I14*J14
B15: Interfaz / consola de podcast multicanal | C15: 1 | D15: 220 | E15: =C15*D15 | F15: 1 | G15: 600 | H15: =F15*G15 | I15: 1 | J15: 750 | K15: =I15*J15
B16: Auriculares cerrados de monitoreo | C16: 4 | D16: 30 | E16: =C16*D16 | F16: 4 | G16: 60 | H16: =F16*G16 | I16: 4 | J16: 90 | K16: =I16*J16
B17: Cable XLR | C17: 6 | D17: 8 | E17: =C17*D17 | F17: 6 | G17: 15 | H17: =F17*G17 | I17: 6 | J17: 20 | K17: =I17*J17
B18: Filtro anti-pop | C18: 4 | D18: 6 | E18: =C18*D18 | F18: 4 | G18: 10 | H18: =F18*G18 | I18: 4 | J18: 10 | K18: =I18*J18
B19: Grabador de respaldo | C19: 1 | D19: 18 | E19: =C19*D19 | F19: 1 | G19: 70 | H19: =F19*G19 | I19: 1 | J19: 120 | K19: =I19*J19
B20: Subtotal AUDIO | E20: =SUM(E13:E19) | H20: =SUM(H13:H19) | K20: =SUM(K13:K19)
A22: ILUMINACIÓN | B22: Panel LED bicolor con softbox | C22: 2 | D22: 110 | E22: =C22*D22 | F22: 2 | G22: 200 | H22: =F22*G22 | I22: 2 | J22: 400 | K22: =I22*J22
B23: Panel LED de recorte (luz trasera) | C23: 0 | D23: 0 | E23: =C23*D23 | F23: 1 | G23: 120 | H23: =F23*G23 | I23: 1 | J23: 250 | K23: =I23*J23
B24: Luz de fondo RGB / lámpara de ambiente | C24: 1 | D24: 45 | E24: =C24*D24 | F24: 2 | G24: 55 | H24: =F24*G24 | I24: 2 | J24: 90 | K24: =I24*J24
B25: Trípode de luz | C25: 2 | D25: 30 | E25: =C25*D25 | F25: 3 | G25: 30 | H25: =F25*G25 | I25: 3 | J25: 55 | K25: =I25*J25
B26: Difusores y banderas | C26: 1 | D26: 55 | E26: =C26*D26 | F26: 1 | G26: 30 | H26: =F26*G26 | I26: 1 | J26: 55 | K26: =I26*J26
B27: Subtotal ILUMINACIÓN | E27: =SUM(E22:E26) | H27: =SUM(H22:H26) | K27: =SUM(K22:K26)
A29: SET Y ACÚSTICA | B29: Butaca individual para entrevista | C29: 0 | D29: 0 | E29: =C29*D29 | F29: 3 | G29: 300 | H29: =F29*G29 | I29: 3 | J29: 550 | K29: =I29*J29
B30: Mesa ratona baja | C30: 0 | D30: 0 | E30: =C30*D30 | F30: 1 | G30: 200 | H30: =F30*G30 | I30: 1 | J30: 350 | K30: =I30*J30
B31: Alfombra (control de rebote del piso) | C31: 1 | D31: 90 | E31: =C31*D31 | F31: 1 | G31: 150 | H31: =F31*G31 | I31: 1 | J31: 300 | K31: =I31*J31
B32: Biblioteca / estantería de fondo | C32: 0 | D32: 0 | E32: =C32*D32 | F32: 1 | G32: 280 | H32: =F32*G32 | I32: 1 | J32: 700 | K32: =I32*J32
B33: Ambientación (libros, objetos, plantas) | C33: 1 | D33: 90 | E33: =C33*D33 | F33: 1 | G33: 150 | H33: =F33*G33 | I33: 1 | J33: 300 | K33: =I33*J33
B34: Paneles acústicos (pack de 12) e instalación | C34: 1 | D34: 250 | E34: =C34*D34 | F34: 1 | G34: 250 | H34: =F34*G34 | I34: 1 | J34: 500 | K34: =I34*J34
B35: Cortinado pesado | C35: 1 | D35: 70 | E35: =C35*D35 | F35: 1 | G35: 100 | H35: =F35*G35 | I35: 1 | J35: 150 | K35: =I35*J35
B36: Mesa auxiliar técnica y perchero | C36: 1 | D36: 60 | E36: =C36*D36 | F36: 1 | G36: 120 | H36: =F36*G36 | I36: 1 | J36: 100 | K36: =I36*J36
B37: Banner / placa con identidad FHC | C37: 1 | D37: 140 | E37: =C37*D37 | F37: 1 | G37: 100 | H37: =F37*G37 | I37: 1 | J37: 50 | K37: =I37*J37
B38: Subtotal SET Y ACÚSTICA | E38: =SUM(E29:E37) | H38: =SUM(H29:H37) | K38: =SUM(K29:K37)
A40: POSPRODUCCIÓN | B40: Notebook / workstation de edición | C40: 0 | D40: 0 | E40: =C40*D40 | F40: 1 | G40: 1000 | H40: =F40*G40 | I40: 1 | J40: 1800 | K40: =I40*J40
B41: Disco SSD externo (2 TB / 4 TB) | C41: 1 | D41: 130 | E41: =C41*D41 | F41: 1 | G41: 150 | H41: =F41*G41 | I41: 1 | J41: 250 | K41: =I41*J41
B42: Lector de tarjetas y accesorios | C42: 1 | D42: 50 | E42: =C42*D42 | F42: 1 | G42: 45 | H42: =F42*G42 | I42: 1 | J42: 50 | K42: =I42*J42
B43: Monitor secundario / calibrado | C43: 0 | D43: 0 | E43: =C43*D43 | F43: 1 | G43: 100 | H43: =F43*G43 | I43: 1 | J43: 200 | K43: =I43*J43
B44: Software de edición (DaVinci Resolve gratuito) | C44: 1 | D44: 0 | E44: =C44*D44 | F44: 1 | G44: 0 | H44: =F44*G44 | I44: 1 | J44: 0 | K44: =I44*J44
B45: Subtotal POSPRODUCCIÓN | E45: =SUM(E40:E44) | H45: =SUM(H40:H44) | K45: =SUM(K40:K44)
...

Sheet OPEX
A1: OPEX — COSTO RECURRENTE POR EPISODIO
A3: Concepto | B3: USD por episodio | C3: Episodios | D3: Total temporada USD | E3: Total temporada ARS | F3: Nota
A4: Edición y posproducción (freelance) | B4: 150 | C4: =Parámetros!$B$7 | D4: =B4*C4 | E4: =D4*Parámetros!$B$4 | F4: Video completo + 6 clips. Alternativa interna: §7.6 del documento
A5: Transcripción y subtítulos | B5: 15 | C5: =Parámetros!$B$7 | D5: =B5*C5 | E5: =D5*Parámetros!$B$4 | F5: Subtítulos + texto para la web (SEO)
A6: Catering para invitado y equipo | B6: 25 | C6: =Parámetros!$B$7 | D6: =B6*C6 | E6: =D6*Parámetros!$B$4 | F6: Café, agua, algo para picar
A7: Traslado del invitado | B7: 25 | C7: =Parámetros!$B$7 | D7: =B7*C7 | E7: =D7*Parámetros!$B$4 | F7: Remis ida y vuelta
A8: Regalo institucional para el invitado | B8: 30 | C8: =Parámetros!$B$7 | D8: =B8*C8 | E8: =D8*Parámetros!$B$4 | F8: Libro del Center o merch
A9: Hosting de podcast (prorrateado) | B9: 13 | C9: =Parámetros!$B$7 | D9: =B9*C9 | E9: =D9*Parámetros!$B$4 | F9: USD 20 mensuales / distribución a Spotify, Apple, etc.
A10: SUBTOTAL POR EPISODIO (sin pauta) | B10: =SUM(B4:B9) | D10: =SUM(D4:D9) | E10: =D10*Parámetros!$B$4
A12: OPCIONAL
A13: Pauta paga en redes | B13: 100 | C13: =Parámetros!$B$12 | D13: =B13*C13 | E13: =D13*Parámetros!$B$4 | F13: No pautar los 3 primeros episodios: primero se ve qué funciona orgánicamente
A15: COSTOS ÚNICOS NO AMORTIZABLES
A16: Registro de marca y dominio | D16: 150 | E16: =D16*Parámetros!$B$4 | F16: Nombre del podcast + dominio + redes
A17: Licencia de música y biblioteca sonora | D17: 120 | E17: =D17*Parámetros!$B$4 | F17: Obligatorio: música sin licencia genera reclamos de copyright que afectan al canal entero
A18: Subtotal costos únicos | D18: =SUM(D16:D17) | E18: =D18*Parámetros!$B$4

Sheet Resumen
A1: RESUMEN — TEMPORADA 1 (12 EPISODIOS)
A3: Concepto | B3: Austero | C3: Recomendado | D3: Premium | E3: ESCENARIO ELEGIDO | F3: ARS (escenario elegido)
A4: CAPEX — equipamiento y set (activo de UCEMA) | B4: =CAPEX!$E$47 | C4: =CAPEX!$H$47 | D4: =CAPEX!$K$47 | E4: =INDEX(B4:D4,MATCH(Parámetros!$B$6,$B$3:$D$3,0)) | F4: =E4*Parámetros!$B$4
A5: OPEX — operación de los 12 episodios | B5: =OPEX!$D$10 | C5: =OPEX!$D$10 | D5: =OPEX!$D$10 | E5: =INDEX(B5:D5,MATCH(Parámetros!$B$6,$B$3:$D$3,0)) | F5: =E5*Parámetros!$B$4
A6: Costos únicos (marca, dominio, música) | B6: =OPEX!$D$18 | C6: =OPEX!$D$18 | D6: =OPEX!$D$18 | E6: =INDEX(B6:D6,MATCH(Parámetros!$B$6,$B$3:$D$3,0)) | F6: =E6*Parámetros!$B$4
A7: SUBTOTAL | B7: =SUM(B4:B6) | C7: =SUM(C4:C6) | D7: =SUM(D4:D6) | E7: =INDEX(B7:D7,MATCH(Parámetros!$B$6,$B$3:$D$3,0)) | F7: =E7*Parámetros!$B$4
A8: Contingencia (10%) | B8: =B7*Parámetros!$B$11 | C8: =C7*Parámetros!$B$11 | D8: =D7*Parámetros!$B$11 | E8: =INDEX(B8:D8,MATCH(Parámetros!$B$6,$B$3:$D$3,0)) | F8: =E8*Parámetros!$B$4
A9: TOTAL SIN PAUTA | B9: =B7+B8 | C9: =C7+C8 | D9: =D7+D8 | E9: =INDEX(B9:D9,MATCH(Parámetros!$B$6,$B$3:$D$3,0)) | F9: =E9*Parámetros!$B$4
A10: Pauta paga (6 de 12 episodios, +contingencia) | B10: =OPEX!$D$13*(1+Parámetros!$B$11) | C10: =OPEX!$D$13*(1+Parámetros!$B$11) | D10: =OPEX!$D$13*(1+Parámetros!$B$11) | E10: =INDEX(B10:D10,MATCH(Parámetros!$B$6,$B$3:$D$3,0)) | F10: =E10*Parámetros!$B$4
A11: TOTAL A SOLICITAR | B11: =B9+B10 | C11: =C9+C10 | D11: =D9+D10 | E11: =INDEX(B11:D11,MATCH(Parámetros!$B$6,$B$3:$D$3,0)) | F11: =E11*Parámetros!$B$4
A14: INDICADORES DE EFICIENCIA
A15: Indicador | B15: Valor USD | F15: Nota
A16: Costo total por episodio (Temporada 1, CAPEX incluido) | B16: =E11/Parámetros!$B$7 | F16: Incluye la inversión de única vez
A17: Costo por episodio a partir de la Temporada 2 | B17: =OPEX!$D$10/Parámetros!$B$7 | F17: Sin CAPEX: es el costo real recurrente
A18: Costo por hora de contenido (1 h por episodio) | B18: =E11/Parámetros!$B$7 | F18: Episodios de 45 a 60 minutos
A19: Costo por contacto nuevo en la base (meta: 600) | B19: =E11/600 | F19: Objetivo O3
A20: Costo por pieza de contenido publicada (108 piezas) | B20: =E11/108 | F20: 12 videos + 12 audios + 72 clips + 12 newsletters
A23: ESQUEMA DE FINANCIAMIENTO PROPUESTO
A24: Fuente | B24: Monto USD | C24: % del total | F24: Contraprestación
A25: Sponsor principal de temporada | B25: 9000 | C25: =B25/SUM($B$25:$B$28)
A26: Sponsor de apoyo 1 | B26: 2000 | C26: =B26/SUM($B$25:$B$28)
A27: Sponsor de apoyo 2 | B27: 2000 | C27: =B27/SUM($B$25:$B$28)
A28: Aporte del FHC | B28: 1300 | C28: =B28/SUM($B$25:$B$28)
A29: TOTAL FINANCIADO | B29: =SUM(B25:B28) | C29: 1
A31: Independencia editorial: ningún sponsor tiene injerencia sobre el contenido, la selección de invitados ni la edición.

Sheet Cronograma
A1: CRONOGRAMA TEMPORADA 1 — UNA PUBLICACIÓN CADA 20 DÍAS
A3: Ep. | B3: Grabación | C3: Publicación | D3: Tema | E3: Perfil target del invitado | F3: Audiencia primaria
A4: E01 | B4: Jue 22/10/26 | C4: Jue 05/11/26 | D4: Por qué la economía no es lo que te contaron | E4: Economista jefe de consultora o think tank, con oficio en medios. Alguien que explica bien, no necesariamente el más citado | F4: Estudiantes
A5: E02 | B5: Jue 12/11/26 | C5: Mié 25/11/26 | D5: Emprender donde todo cambia | E5: Fundador/a de PyME o scale-up argentina, 5 a 15 años de trayectoria, que haya atravesado al menos una crisis | F5: Alumni y profesionales
A6: E03 | B6: Mié 02/12/26 | C6: Mar 15/12/26 | D6: La ley como límite al poder | E6: Constitucionalista, juez o profesor de Derecho Público. Que hable claro, no en latín | F6: Estudiantes de Derecho
A7: E04 | B7: Jue 17/12/26 (AM) | C7: Lun 04/01/27 | D7: De dónde venimos: historia de las ideas de la libertad en Argentina | E7: Historiador/a de las ideas o investigador académico con libro publicado | F7: Comunidad de ideas
A8: E05 | B8: Jue 17/12/26 (PM) | C8: Lun 25/01/27 | D8: Qué hacer con lo que ganás: ahorro e inversión | E8: Portfolio manager, analista de research o fundador de fintech de inversión | F8: Alumni y profesionales
A9: E06 | B9: Mié 03/02/27 | C9: Lun 15/02/27 | D9: Decir lo que no conviene: libertad de expresión y prensa | E9: Periodista, editor o director de medio. Preferentemente alguien que haya pagado un costo por publicar algo | F9: Terciaria y prensa
A10: E07 | B10: Mié 24/02/27 | C10: Vie 05/03/27 | D10: Poder sin permiso: tecnología, cripto y descentralización | E10: Founder o CTO del ecosistema cripto/fintech regional | F10: Estudiantes y terciaria
A11: E08 | B11: Mié 17/03/27 | C11: Mar 30/03/27 | D11: Reformar el Estado desde adentro | E11: Ex funcionario técnico o cuadro de gestión pública, nacional o provincial | F11: Alumni e institucional
A12: E09 | B12: Jue 01/04/27 | C12: Mié 14/04/27 | D12: Aprender de otra manera: educación, competencia y elección | E12: Director/a de colegio o universidad con modelo alternativo, o fundador de edtech | F12: Estudiantes y docentes
A13: E10 | B13: Mié 21/04/27 | C13: Mar 04/05/27 | D13: La objeción: las críticas más serias al liberalismo | E13: Filósofo político o académico QUE NO SE IDENTIFIQUE COMO LIBERAL. Episodio deliberadamente incómodo | F13: Comunidad de ideas
A14: E11 | B14: Mié 12/05/27 | C14: Lun 24/05/27 | D14: El país que exporta: agro, comercio internacional y apertura | E14: Empresario agroexportador o especialista en comercio exterior | F14: Alumni y terciaria
A15: E12 | B15: Mié 02/06/27 | C15: Lun 14/06/27 | D15: Los que vienen: la generación que recién empieza | E15: Alumni joven del FHC (menos de 30), emprendedor o líder estudiantil | F15: Estudiantes
A17: • | B17: La cadencia de 20 días se aplica sobre la fecha de PUBLICACIÓN. La grabación va entre 9 y 13 días antes, siempre martes, miércoles o jueves.
A18: • | B18: Si la publicación cae sábado o domingo, se corre al lunes siguiente.
A19: • | B19: Las grabaciones de los episodios de enero se adelantan a una jornada doble el 17/12/2026, para no pedirle a nadie que venga en pleno receso.
A20: • | B20: E02 se publica el 25/11, un día antes de las Jornadas Adam Smith (26/11): sirve de antesala. No hay grabación esa semana.
A21: • | B21: PENDIENTE: validar feriados 2027 contra el calendario oficial. Revisar E06 (Carnaval), E08 (Semana Santa) y E11 (25 de mayo).
A22: • | B22: Oportunidad: los expositores del Ayn Rand Center (29/10) y de las Jornadas Adam Smith (26/11) ya vienen a la universidad. Grabar el mismo día elimina el costo de traerlos.

Sheet Horas internas
A1: HORAS INTERNAS — NO IMPLICA DESEMBOLSO, PERO ES EL RECURSO MÁS ESCASO
A3: Rol | B3: Persona | C3: Horas por episodio | D3: Horas temporada | E3: Detalle
A4: Coordinación editorial y contacto con invitados | B4: Frank | C4: 4 | D4: =C4*Parámetros!$B$7 | E4: Selección de temas, invitación, investigación previa, guion, revisión del corte
A5: Diseño, clips y difusión | B5: Paz | C5: 6 | D5: =C5*Parámetros!$B$7 | E5: Portada en Canva, 5 a 7 clips verticales, carrusel de citas, publicación en redes
A6: Logística, grabación y publicación | B6: Matías | C6: 7 | D6: =C6*Parámetros!$B$7 | E6: Aula, lista de seguridad, catering, armado del set, grabación, respaldo, subida a YouTube, métricas
A7: Web, formularios y envíos | B7: Martina | C7: 3 | D7: =C7*Parámetros!$B$7 | E7: Transcripción, publicación en la web, envío en Perfit, carga en la Base Maestra
A8: TOTAL | C8: =SUM(C4:C7) | D8: =SUM(D4:D7)
A10: 240 horas en ocho meses ≈ 7 horas semanales repartidas entre cuatro personas. Es sostenible, pero solo si el proyecto entra en Asana con la misma disciplina que el resto de las actividades.
